<?xml version='1.0' encoding='utf-8'?>
<robot name="X5A">
  <link name="x5a_link0">
    <inertial>
      <origin xyz="-3.0001E-05 3.0589E-05 0.027324" rpy="0 0 0" />
      <mass value="0.43995" />
      <inertia ixx="0.00017" ixy="0.00000" ixz="0.00000" iyy="0.00017" iyz="0.00000" izz="0.00016" />
    </inertial>
    <visual>
      <origin xyz="0 0 0" rpy="0 0 0" />
      <geometry>
        <mesh filename="meshes/base_link.STL" />
      </geometry>
      <material name="black">
        <color rgba="0 0 0 1" />
      </material>
    </visual>
    <collision>
      <origin xyz="0 0 0" rpy="0 0 0" />
      <geometry>
        <mesh filename="meshes/base_link.STL" />
      </geometry>
    </collision>
  </link>
  <link name="x5a_link1">
    <inertial>
      <origin xyz="0.0054231 -0.0080289 0.017086" rpy="0 0 0" />
      <mass value="0.066982" />
      <inertia ixx="0.00008" ixy="0.00000" ixz="0.00001" iyy="0.00003" iyz="0.00000" izz="0.00008" />
    </inertial>
    <visual>
      <origin xyz="0 0 0" rpy="0 0 0" />
      <geometry>
        <mesh filename="meshes/link1.STL" />
      </geometry>
      <material name="black">
        <color rgba="0 0 0 1" />
      </material>
    </visual>
    <collision>
      <origin xyz="0 0 0" rpy="0 0 0" />
      <geometry>
        <mesh filename="meshes/link1.STL" />
      </geometry>
    </collision>
  </link>
  <joint name="x5a_joint1" type="revolute">
    <origin xyz="0 0 0.0605" rpy="0 0 0" />
    <parent link="x5a_link0" />
    <child link="x5a_link1" />
    <axis xyz="0 0 1" />
    <limit lower="-10" upper="10" effort="100" velocity="1000" />
  </joint>
  <link name="x5a_link2">
    <inertial>
      <origin xyz="-0.13237 0.0020852 0.00010549" rpy="0 0 0" />
      <mass value="1.0795" />
      <inertia ixx="0.00051" ixy="0.00001" ixz="-0.00004" iyy="0.01599" iyz="0.00000" izz="0.01605" />
    </inertial>
    <visual>
      <origin xyz="0 0 0" rpy="0 0 0" />
      <geometry>
        <mesh filename="meshes/link2.STL" />
      </geometry>
      <material name="black">
        <color rgba="0 0 0 1" />
      </material>
    </visual>
    <collision>
      <origin xyz="0 0 0" rpy="0 0 0" />
      <geometry>
        <mesh filename="meshes/link2.STL" />
      </geometry>
    </collision>
  </link>
  <joint name="x5a_joint2" type="revolute">
    <origin xyz="0.02 0 0.04" rpy="0 0 0" />
    <parent link="x5a_link1" />
    <child link="x5a_link2" />
    <axis xyz="0 1 0" />
    <limit lower="-10" upper="10" effort="100" velocity="1000" />
  </joint>
  <link name="x5a_link3">
    <inertial>
      <origin xyz="0.18531 0.00068376 -0.051638" rpy="0 0 0" />
      <mass value="0.54534" />
      <inertia ixx="0.00036" ixy="-0.00003" ixz="-0.00039" iyy="0.00423" iyz="0.00001" izz="0.00420" />
    </inertial>
    <visual>
      <origin xyz="0 0 0" rpy="0 0 0" />
      <geometry>
        <mesh filename="meshes/link3.STL" />
      </geometry>
      <material name="white">
        <color rgba="1 1 1 1" />
      </material>
    </visual>
    <collision>
      <origin xyz="0 0 0" rpy="0 0 0" />
      <geometry>
        <mesh filename="meshes/link3.STL" />
      </geometry>
    </collision>
  </link>
  <joint name="x5a_joint3" type="revolute">
    <origin xyz="-0.264 0 0" rpy="3.1416 0 0" />
    <parent link="x5a_link2" />
    <child link="x5a_link3" />
    <axis xyz="0 1 0" />
    <limit lower="-10" upper="10" effort="100" velocity="1000" />
  </joint>
  <link name="x5a_link4">
    <inertial>
      <origin xyz="0.040231 0.0044807 -0.035335" rpy="0 0 0" />
      <mass value="0.11714" />
      <inertia ixx="0.00019" ixy="-0.00002" ixz="-0.00009" iyy="0.00023" iyz="0.00002" izz="0.00014" />
    </inertial>
    <visual>
      <origin xyz="0 0 0" rpy="0 0 0" />
      <geometry>
        <mesh filename="meshes/link4.STL" />
      </geometry>
      <material name="black">
        <color rgba="0 0 0 1" />
      </material>
    </visual>
    <collision>
      <origin xyz="0 0 0" rpy="0 0 0" />
      <geometry>
        <mesh filename="meshes/link4.STL" />
      </geometry>
    </collision>
  </link>
  <joint name="x5a_joint4" type="revolute">
    <origin xyz="0.245 0 -0.056" rpy="0 0 0" />
    <parent link="x5a_link3" />
    <child link="x5a_link4" />
    <axis xyz="0 1 0" />
    <limit lower="-10" upper="10" effort="100" velocity="1000" />
  </joint>
  <link name="x5a_link5">
    <inertial>
      <origin xyz="0.003612 -1.5455E-05 0.055214" rpy="0 0 0" />
      <mass value="0.63488" />
      <inertia ixx="0.00083" ixy="0.00000" ixz="0.00007" iyy="0.00082" iyz="0.00000" izz="0.00026" />
    </inertial>
    <visual>
      <origin xyz="0 0 0" rpy="0 0 0" />
      <geometry>
        <mesh filename="meshes/link5.STL" />
      </geometry>
      <material name="black">
        <color rgba="0 0 0 1" />
      </material>
    </visual>
    <collision>
      <origin xyz="0 0 0" rpy="0 0 0" />
      <geometry>
        <mesh filename="meshes/link5.STL" />
      </geometry>
    </collision>
  </link>
  <joint name="x5a_joint5" type="revolute">
    <origin xyz="0.06775 0.0005 -0.0865" rpy="0 0 0" />
    <parent link="x5a_link4" />
    <child link="x5a_link5" />
    <axis xyz="0 0 1" />
    <limit lower="-10" upper="10" effort="100" velocity="1000" />
  </joint>
  <link name="x5a_link6">
    <inertial>
      <origin xyz="0.041697 2.4368E-05 0.00014464" rpy="0 0 0" />
      <mass value="0.44089" />
      <inertia ixx="0.00038" ixy="0.00000" ixz="0.00000" iyy="0.00028" iyz="0.00000" izz="0.00050" />
    </inertial>
    <visual>
      <origin xyz="0 0 0" rpy="0 0 0" />
      <geometry>
        <mesh filename="meshes/link6.STL" />
      </geometry>
      <material name="black">
        <color rgba="0 0 0 1" />
      </material>
    </visual>
    <collision>
      <origin xyz="0 0 0" rpy="0 0 0" />
      <geometry>
        <mesh filename="meshes/link6.STL" />
      </geometry>
    </collision>
  </link>
  <joint name="x5a_joint6" type="revolute">
    <origin xyz="0.02895 0 0.0865" rpy="-3.1416 0 0" />
    <parent link="x5a_link5" />
    <child link="x5a_link6" />
    <axis xyz="1 0 0" />
    <limit lower="-3.14" upper="3.14" effort="100" velocity="1000" />
  </joint>
  <link name="x5a_camera_base">
    <visual>
      <origin xyz="0 0 0.0" rpy="0 0 0" />
      <geometry>
        <mesh filename="meshes/camera_base.glb" />
      </geometry>
    </visual>
  </link>
  <joint name="x5a_hand_to_camera_mount" type="fixed">
    <parent link="x5a_link6" />
    <child link="x5a_camera_base" />
    <origin xyz="0.057 0 0" rpy="0 0 -3.1416" />
  </joint>
  <link name="x5a_camera">
    <visual>
      <origin rpy="0.0 0.0 -1.5707963267948966" xyz="0.0 0.0 -0.0" />
      <geometry>
        <mesh filename="meshes/camera.glb" />
      </geometry>
    </visual>
  </link>
  <joint name="x5a_camera_joint" type="fixed">
    <parent link="x5a_camera_base" />
    <child link="x5a_camera" />
    <origin xyz="-0.0275 0.0 0.05" rpy="0 0.3491 3.141592653589793" />
  </joint>
  <link name="x5a_adapter_link">
    <inertial>
      <origin xyz="0 0 0" rpy="0 0 0" />
      <mass value="0.001" />
      <inertia ixx="1e-6" ixy="0" ixz="0" iyy="1e-6" iyz="0" izz="1e-6" />
    </inertial>
  </link>
  <joint name="x5a_link6_to_adapter" type="fixed">
    <parent link="x5a_link6" />
    <child link="x5a_adapter_link" />
    <origin xyz="-0.008402782 0 0" rpy="0 0 0" />
  </joint>
  <link name="x5a_adapter_left_link">
    <inertial>
      <origin xyz="0 0 0" rpy="0 0 0" />
      <mass value="0.2" />
      <inertia ixx="0.0001" ixy="0" ixz="0" iyy="0.0001" iyz="0" izz="0.0001" />
    </inertial>
    <visual name="adapter_left_visual">
      <origin xyz="-0.004 0 -0.002" rpy="1.57079632679 0 0" />
      <geometry>
        <mesh filename="meshes/adapter_left.STL" scale="0.001 0.001 0.001" />
      </geometry>
      <material name="adapter_gray">
        <color rgba="0.7 0.7 0.7 1" />
      </material>
    </visual>
    <collision name="adapter_left_collision">
      <origin xyz="-0.004 0 -0.002" rpy="1.57079632679 0 0" />
      <geometry>
        <mesh filename="meshes/adapter_left.STL" scale="0.001 0.001 0.001" />
      </geometry>
    </collision>
    <visual name="slip_adapter_left_visual">
      <origin xyz="-0.017 -0.015 -0.0148" rpy="1.57079632679 1.57079632679 0" />
      <geometry>
        <mesh filename="meshes/slip_adapter.STL" scale="0.001 0.001 0.001" />
      </geometry>
    </visual>
    <collision name="slip_adapter_left_collision">
      <origin xyz="-0.017 -0.015 -0.0148" rpy="1.57079632679 1.57079632679 0" />
      <geometry>
        <mesh filename="meshes/slip_adapter.STL" scale="0.001 0.001 0.001" />
      </geometry>
    </collision>
    <visual name="xensews_left_visual">
      <origin xyz="0.044 -0.015535 -0.015038" rpy="3.14159265359 0 0" />
      <geometry>
        <mesh filename="meshes/XenseWS.STL" scale="0.001 0.001 0.001" />
      </geometry>
      <material name="xensews_gray">
        <color rgba="0.5 0.5 0.5 1" />
      </material>
    </visual>
    <collision name="xensews_left_collision">
      <origin xyz="0.044 -0.015535 -0.015038" rpy="3.14159265359 0 0" />
      <geometry>
        <mesh filename="meshes/XenseWS.STL" scale="0.001 0.001 0.001" />
      </geometry>
    </collision>
  </link>
  <joint name="x5a_adapter_left_mount" type="prismatic">
    <parent link="x5a_adapter_link" />
    <child link="x5a_adapter_left_link" />
    <origin xyz="0.09657 0.04999 0.015638" rpy="0 0 0" />
    <axis xyz="0 1 0" />
    <limit lower="-0.015" upper="0.06" effort="100" velocity="0.2" />
  </joint>
  <link name="x5a_adapter_right_link">
    <inertial>
      <origin xyz="0 0 0" rpy="0 0 0" />
      <mass value="0.2" />
      <inertia ixx="0.0001" ixy="0" ixz="0" iyy="0.0001" iyz="0" izz="0.0001" />
    </inertial>
    <visual name="adapter_right_visual">
      <origin xyz="-0.0025 0 -0.002" rpy="1.57079632679 0 0" />
      <geometry>
        <mesh filename="meshes/adapter_right.STL" scale="0.001 0.001 0.001" />
      </geometry>
      <material name="adapter_gray" />
    </visual>
    <collision name="adapter_right_collision">
      <origin xyz="-0.0025 0 -0.002" rpy="1.57079632679 0 0" />
      <geometry>
        <mesh filename="meshes/adapter_right.STL" scale="0.001 0.001 0.001" />
      </geometry>
    </collision>
    <visual name="slip_adapter_right_visual">
      <origin xyz="-0.017 0.015 -0.015" rpy="1.57079632679 1.57079632679 0" />
      <geometry>
        <mesh filename="meshes/slip_adapter.STL" scale="0.001 0.001 0.001" />
      </geometry>
    </visual>
    <collision name="slip_adapter_right_collision">
      <origin xyz="-0.017 0.015 -0.015" rpy="1.57079632679 1.57079632679 0" />
      <geometry>
        <mesh filename="meshes/slip_adapter.STL" scale="0.001 0.001 0.001" />
      </geometry>
    </collision>
    <visual name="xensews_right_visual">
      <origin xyz="0.046 0.015045 -0.015038" rpy="0 0 0" />
      <geometry>
        <mesh filename="meshes/XenseWS.STL" scale="0.001 0.001 0.001" />
      </geometry>
      <material name="xensews_gray">
        <color rgba="0.5 0.5 0.5 1" />
      </material>
    </visual>
    <collision name="xensews_right_collision">
      <origin xyz="0.046 0.015045 -0.015038" rpy="0 0 0" />
      <geometry>
        <mesh filename="meshes/XenseWS.STL" scale="0.001 0.001 0.001" />
      </geometry>
    </collision>
  </link>
  <joint name="x5a_adapter_right_mount" type="prismatic">
    <parent link="x5a_adapter_link" />
    <child link="x5a_adapter_right_link" />
    <origin xyz="0.09657 -0.0489 0.015638" rpy="0 0 0" />
    <axis xyz="0 -1 0" />
    <limit lower="-0.015" upper="0.06" effort="100" velocity="0.2" />
  </joint>
  <link name="x5a_xensews_gripper_center">
    <inertial>
      <origin xyz="0 0 0" rpy="0 0 0" />
      <mass value="0.001" />
      <inertia ixx="1e-6" ixy="0" ixz="0" iyy="1e-6" iyz="0" izz="1e-6" />
    </inertial>
  </link>
  <joint name="x5a_adapter_link_to_xensews_gripper_center" type="fixed">
    <parent link="x5a_adapter_link" />
    <child link="x5a_xensews_gripper_center" />
    <origin xyz="0.151250082 0.000545 -0.002764835" rpy="3.1415 0 0" />
  </joint>
</robot>