<?xml version='1.0' encoding='utf-8'?>
<robot name="X5A">
  <link name="x5a_link0">
    <inertial>
      <origin xyz="-0.000035704 0.000030589 0.032517801" rpy="0 0 0" />
      <mass value="0.43995" />
      <inertia ixx="0.00017" ixy="0.00000" ixz="0.00000" iyy="0.00017" iyz="0.00000" izz="0.00016" />
    </inertial>
    <visual>
      <origin xyz="0 0 0" rpy="0 0 0" />
      <geometry>
        <mesh filename="meshes/x5a_link0.STL" scale="1.190082 1 1.190082" />
      </geometry>
      <material name="black">
        <color rgba="0 0 0 1" />
      </material>
    </visual>
    <collision>
      <origin xyz="0 0 0" rpy="0 0 0" />
      <geometry>
        <mesh filename="meshes/x5a_link0.STL" scale="1.190082 1 1.190082" />
      </geometry>
    </collision>
  </link>
  <link name="x5a_link1">
    <inertial>
      <origin xyz="0.006453934 -0.0080289 0.020333741" rpy="0 0 0" />
      <mass value="0.066982" />
      <inertia ixx="0.00008" ixy="0.00000" ixz="0.00001" iyy="0.00003" iyz="0.00000" izz="0.00008" />
    </inertial>
    <visual>
      <origin xyz="0 0 0" rpy="0 0 0" />
      <geometry>
        <mesh filename="meshes/x5a_link1.STL" scale="1.190082 1 1.190082" />
      </geometry>
      <material name="black">
        <color rgba="0 0 0 1" />
      </material>
    </visual>
    <collision>
      <origin xyz="0 0 0" rpy="0 0 0" />
      <geometry>
        <mesh filename="meshes/x5a_link1.STL" scale="1.190082 1 1.190082" />
      </geometry>
    </collision>
  </link>
  <joint name="x5a_joint1" type="revolute">
    <origin xyz="0 0 0.071999961" rpy="0 0 0" />
    <parent link="x5a_link0" />
    <child link="x5a_link1" />
    <axis xyz="0 0 1" />
    <limit lower="-10" upper="10" effort="100" velocity="1000" />
  </joint>
  <link name="x5a_link2">
    <inertial>
      <origin xyz="-0.157531154 0.0020852 0.000125542" rpy="0 0 0" />
      <mass value="1.0795" />
      <inertia ixx="0.00051" ixy="0.00001" ixz="-0.00004" iyy="0.01599" iyz="0.00000" izz="0.01605" />
    </inertial>
    <visual>
      <origin xyz="0 0 0" rpy="0 0 0" />
      <geometry>
        <mesh filename="meshes/x5a_link2.STL" scale="1.190082 1 1.190082" />
      </geometry>
      <material name="black">
        <color rgba="0 0 0 1" />
      </material>
    </visual>
    <collision>
      <origin xyz="0 0 0" rpy="0 0 0" />
      <geometry>
        <mesh filename="meshes/x5a_link2.STL" scale="1.190082 1 1.190082" />
      </geometry>
    </collision>
  </link>
  <joint name="x5a_joint2" type="revolute">
    <origin xyz="0.02380164 0 0.04760328" rpy="0 0 0" />
    <parent link="x5a_link1" />
    <child link="x5a_link2" />
    <axis xyz="0 1 0" />
    <limit lower="-10" upper="10" effort="100" velocity="1000" />
  </joint>
  <link name="x5a_link3">
    <inertial>
      <origin xyz="0.220534095 0.00068376 -0.061453454" rpy="0 0 0" />
      <mass value="0.54534" />
      <inertia ixx="0.00036" ixy="-0.00003" ixz="-0.00039" iyy="0.00423" iyz="0.00001" izz="0.00420" />
    </inertial>
    <visual>
      <origin xyz="0 0 0" rpy="0 0 0" />
      <geometry>
        <mesh filename="meshes/x5a_link3.STL" scale="1.190082 1 1.190082" />
      </geometry>
      <material name="white">
        <color rgba="1 1 1 1" />
      </material>
    </visual>
    <collision>
      <origin xyz="0 0 0" rpy="0 0 0" />
      <geometry>
        <mesh filename="meshes/x5a_link3.STL" scale="1.190082 1 1.190082" />
      </geometry>
    </collision>
  </link>
  <joint name="x5a_joint3" type="revolute">
    <origin xyz="-0.314181648 0 0" rpy="3.1416 0 0" />
    <parent link="x5a_link2" />
    <child link="x5a_link3" />
    <axis xyz="0 1 0" />
    <limit lower="-10" upper="10" effort="100" velocity="1000" />
  </joint>
  <link name="x5a_link4">
    <inertial>
      <origin xyz="0.047878189 0.0044807 -0.042051547" rpy="0 0 0" />
      <mass value="0.11714" />
      <inertia ixx="0.00019" ixy="-0.00002" ixz="-0.00009" iyy="0.00023" iyz="0.00002" izz="0.00014" />
    </inertial>
    <visual>
      <origin xyz="0 0 0" rpy="0 0 0" />
      <geometry>
        <mesh filename="meshes/x5a_link4.STL" scale="1.190082 1 1.190082" />
      </geometry>
      <material name="black">
        <color rgba="0 0 0 1" />
      </material>
    </visual>
    <collision>
      <origin xyz="0 0 0" rpy="0 0 0" />
      <geometry>
        <mesh filename="meshes/x5a_link4.STL" scale="1.190082 1 1.190082" />
      </geometry>
    </collision>
  </link>
  <joint name="x5a_joint4" type="revolute">
    <origin xyz="0.29157009 0 -0.066644592" rpy="0 0 0" />
    <parent link="x5a_link3" />
    <child link="x5a_link4" />
    <axis xyz="0 1 0" />
    <limit lower="-10" upper="10" effort="100" velocity="1000" />
  </joint>
  <link name="x5a_link5">
    <inertial>
      <origin xyz="0.004298576 -0.000015455 0.065709188" rpy="0 0 0" />
      <mass value="0.63488" />
      <inertia ixx="0.00083" ixy="0.00000" ixz="0.00007" iyy="0.00082" iyz="0.00000" izz="0.00026" />
    </inertial>
    <visual>
      <origin xyz="0 0 0" rpy="0 0 0" />
      <geometry>
        <mesh filename="meshes/x5a_link5.STL" scale="1.190082 1 1.190082" />
      </geometry>
      <material name="black">
        <color rgba="0 0 0 1" />
      </material>
    </visual>
    <collision>
      <origin xyz="0 0 0" rpy="0 0 0" />
      <geometry>
        <mesh filename="meshes/x5a_link5.STL" scale="1.190082 1 1.190082" />
      </geometry>
    </collision>
  </link>
  <joint name="x5a_joint5" type="revolute">
    <origin xyz="0.080628056 0.0005 -0.102942093" rpy="0 0 0" />
    <parent link="x5a_link4" />
    <child link="x5a_link5" />
    <axis xyz="0 0 1" />
    <limit lower="-10" upper="10" effort="100" velocity="1000" />
  </joint>
  <link name="x5a_link6">
    <inertial>
      <origin xyz="0.049622849 0.000024368 0.000172133" rpy="0 0 0" />
      <mass value="0.44089" />
      <inertia ixx="0.00038" ixy="0.00000" ixz="0.00000" iyy="0.00028" iyz="0.00000" izz="0.00050" />
    </inertial>
    <visual>
      <origin xyz="0 0 0" rpy="0 0 0" />
      <geometry>
        <mesh filename="meshes/x5a_link6.STL" scale="1.190082 1 1.190082" />
      </geometry>
      <material name="black">
        <color rgba="0 0 0 1" />
      </material>
    </visual>
    <collision>
      <origin xyz="0 0 0" rpy="0 0 0" />
      <geometry>
        <mesh filename="meshes/x5a_link6.STL" scale="1.190082 1 1.190082" />
      </geometry>
    </collision>
  </link>
  <joint name="x5a_joint6" type="revolute">
    <origin xyz="0.034452874 0 0.102942093" rpy="-3.1416 0 0" />
    <parent link="x5a_link5" />
    <child link="x5a_link6" />
    <axis xyz="1 0 0" />
    <limit lower="-3.14" upper="3.14" effort="100" velocity="1000" />
  </joint>
  <link name="x5a_camera_base">
    <visual>
      <origin xyz="0 0 0.0" rpy="0 0 0" />
      <geometry>
        <mesh filename="meshes/camera_base.glb" scale="1.190082 1 1.019834623" />
      </geometry>
    </visual>
  </link>
  <joint name="x5a_hand_to_camera_mount" type="fixed">
    <parent link="x5a_link6" />
    <child link="x5a_camera_base" />
    <origin xyz="0.067834674 0 0" rpy="0 0 -3.1416" />
  </joint>
  <link name="x5a_camera">
    <visual>
      <origin rpy="0.0 0.0 -1.5707963267948966" xyz="0.0 0.0 -0.0" />
      <geometry>
        <mesh filename="meshes/camera.glb" />
      </geometry>
    </visual>
  </link>
  <joint name="x5a_camera_joint" type="fixed">
    <parent link="x5a_camera_base" />
    <child link="x5a_camera" />
    <origin xyz="-0.032727255 0 0.0595041" rpy="0 0.3491 3.141592653589793" />
  </joint>
  <link name="x5a_adapter_link">
    <inertial>
      <origin xyz="0 0 0" rpy="0 0 0" />
      <mass value="0.001" />
      <inertia ixx="1e-6" ixy="0" ixz="0" iyy="1e-6" iyz="0" izz="1e-6" />
    </inertial>
  </link>
  <joint name="x5a_link6_to_adapter" type="fixed">
    <parent link="x5a_link6" />
    <child link="x5a_adapter_link" />
    <origin xyz="-0.01 0 0" rpy="0 0 0" />
  </joint>
  <link name="x5a_adapter_left_link">
    <inertial>
      <origin xyz="0 0 0" rpy="0 0 0" />
      <mass value="0.2" />
      <inertia ixx="0.0001" ixy="0" ixz="0" iyy="0.0001" iyz="0" izz="0.0001" />
    </inertial>
    <visual>
      <origin xyz="0 0 0" rpy="1.5708 0 0" />
      <geometry>
        <mesh filename="meshes/adapter_left.STL" scale="0.001 0.001 0.001" />
      </geometry>
      <material name="adapter_gray">
        <color rgba="0.7 0.7 0.7 1" />
      </material>
    </visual>
    <!-- Second mesh in the same link: edit this origin to tune XenseWS relative to adapter_left. -->
    <visual name="xensews_visual">
      <origin xyz="0.045 -0.015 -0.01" rpy="3.141593 0 0" />
      <geometry>
        <mesh filename="meshes/XenseWS.STL" scale="0.001 0.001 0.001" />
      </geometry>
      <material name="xensews_gray">
        <color rgba="0.5 0.5 0.5 1" />
      </material>
    </visual>
    <collision>
      <origin xyz="0 0 0" rpy="1.5708 0 0" />
      <geometry>
        <mesh filename="meshes/adapter_left.STL" scale="0.001 0.001 0.001" />
      </geometry>
    </collision>
    <!-- Optional: enable this collision if you want XenseWS to participate in collision checks. -->
    <collision name="xensews_collision">
      <origin xyz="0.045 -0.015 -0.01" rpy="3.141593 0 0" />
      <geometry>
        <mesh filename="meshes/XenseWS.STL" scale="0.001 0.001 0.001" />
      </geometry>
    </collision>
  </link>
  <joint name="x5a_adapter_left_mount" type="prismatic">
    <parent link="x5a_adapter_link" />
    <child link="x5a_adapter_left_link" />
    <origin xyz="0.103025399 0.04999 0.00670962" rpy="0 0 0" />
    <axis xyz="0 1 0" />
    <limit lower="0.0" upper="0.025" effort="100" velocity="0.2" />
  </joint>
  <link name="x5a_adapter_right_link">
    <inertial>
      <origin xyz="0 0 0" rpy="0 0 0" />
      <mass value="0.2" />
      <inertia ixx="0.0001" ixy="0" ixz="0" iyy="0.0001" iyz="0" izz="0.0001" />
    </inertial>
    <visual>
      <origin xyz="0 0 0" rpy="1.5708 0 0" />
      <geometry>
        <mesh filename="meshes/adapter_right.STL" scale="0.001 0.001 0.001" />
      </geometry>
      <material name="adapter_gray" />
    </visual>
        <visual name="xensews_visual">
      <origin xyz="0.045 0.015 -0.01" rpy="0 0 0" />
      <geometry>
        <mesh filename="meshes/XenseWS.STL" scale="0.001 0.001 0.001" />
      </geometry>
      <material name="xensews_gray">
        <color rgba="0.5 0.5 0.5 1" />
      </material>
    </visual>
    <collision>
      <origin xyz="0 0 0" rpy="1.5708 0 0" />
      <geometry>
        <mesh filename="meshes/adapter_right.STL" scale="0.001 0.001 0.001" />
      </geometry>
    </collision>
    <collision name="xensews_right_collision">
  <origin xyz="0.045 0.015 -0.01" rpy="0 0 0" />
  <geometry>
    <mesh filename="meshes/XenseWS.STL" scale="0.001 0.001 0.001" />
  </geometry>
</collision>
  </link>
  <joint name="x5a_adapter_right_mount" type="prismatic">
    <parent link="x5a_adapter_link" />
    <child link="x5a_adapter_right_link" />
    <origin xyz="0.103025399 -0.0489 0.00670962" rpy="0 0 0" />
    <axis xyz="0 -1 0" />
    <limit lower="0.0" upper="0.025" effort="100" velocity="0.2" />
  </joint>
  <link name="x5a_xensews_gripper_center">
    <inertial>
      <origin xyz="0 0 0" rpy="0 0 0" />
      <mass value="0.001" />
      <inertia ixx="1e-6" ixy="0" ixz="0" iyy="1e-6" iyz="0" izz="1e-6" />
    </inertial>
  </link>
  <joint name="x5a_adapter_link_to_xensews_gripper_center" type="fixed">
    <parent link="x5a_adapter_link" />
    <child link="x5a_xensews_gripper_center" />
    <origin xyz="0.18 0.000545 -0.00329038" rpy="3.1415 0 0" />
  </joint>

</robot>
